<mujoco model="rat">
  <compiler angle="radian"/>

  <visual>
    <quality shadowsize="2048"/>
    <!-- <global offwidth="1920" offheight="1200" elevation="-20" azimuth="120"/> -->
  </visual>
  
  <statistic meansize="0.003"/>
  
  <asset>
    <texture type="skybox" builtin="gradient" rgb1=".3 .5 .7" rgb2="0 0 0" width="32" height="512"/>
    <texture name="body" type="cube" builtin="flat" mark="cross" width="128" height="128" rgb1="0.8 0.6 0.4" rgb2="0.8 0.6 0.4" markrgb="1 1 1" random="0.01"/>
    <material name="body" texture="body" texuniform="true" rgba="0.8 0.6 .4 1"/>
    <texture name="grid" type="2d" builtin="checker" width="512" height="512" rgb1=".1 .2 .3" rgb2=".2 .3 .4"/>
    <material name="grid" texture="grid" texrepeat="1 1" texuniform="true" reflectance=".2"/>
  </asset>

  <default>
    <joint limited="true" solreflimit="0.01 1" solimplimit="0.99 0.9999 0" armature="6e-07" damping="0.001"/>
    <geom friction="0.7 0.005 0.0001" solref="0.005 1"/>
    <site group="3" rgba="0 0 1 1"/>
    <general ctrllimited="true" ctrlrange="-1 1" forcelimited="false" gainprm="0.01"/>
    <default class="bone">
      <geom contype="0" conaffinity="0" group="0" rgba="0.5 0.5 0.5 1" density="1100.0"/>
    </default>
    <default class="no_collision">
      <geom contype="0" conaffinity="0" condim="3" group="2"/>
    </default>
    <default class="collision">
      <geom contype="1" conaffinity="1" condim="3" group="2"/>
      <default class="collision_primitive">
        <geom type="capsule" group="2" rgba="0 0.5 0.5 1" density="500.0"/>
        <default class="collision_primitive_paw">
          <geom condim="3" priority="1" rgba="0 0.6 0.7 1" friction="1.5 0.005 0.0001"/>
        </default>
        <default class="nonself_collision_primitive_paw">
          <geom conaffinity="0" priority="1" rgba="0 0.6 0.7 1" friction="1.5 0.005 0.0001"/>
        </default>
      </default>
    </default>
    <default class="collision_floor">
      <geom contype="0" conaffinity="1" condim="3"/>
    </default>
    <default class="lumbar">
      <joint group="3" pos="0.003 0 -0.003" armature="1e-05" damping="0.03" solimplimit="0 .99 .01"/>
      <general gainprm="0.15"/>
      <default class="lumbar_extend">
        <joint stiffness="0.02" range="-0.5235987755982988 0.7853981633974483"/>
        <general gainprm="0.4"/>
      </default>
      <default class="lumbar_bend">
        <joint stiffness="0.03" range="-0.5235987755982988 0.5235987755982988"/>
      </default>
      <default class="lumbar_twist">
        <joint stiffness="0.03" range="-0.5235987755982988 0.5235987755982988"/>
      </default>
    </default>
    <default class="cervical">
      <joint group="3" pos="-0.02 0 -0.05" stiffness="1.0" armature="0.001" damping="1.0" solimplimit="0 .99 .01"/>
      <default class="cervical_extend">
        <joint range="-0.4072434921320102 0.6108652381980153"/>
        <general gainprm="2.5"/>
      </default>
      <default class="cervical_bend">
        <joint range="-0.6108652381980153 0.6108652381980153"/>
        <general gainprm="2.5"/>
      </default>
      <default class="cervical_twist">
        <joint range="-0.6108652381980153 0.6108652381980153"/>
        <general gainprm="2.5"/>
      </default>
    </default>
    <default class="atlas">
      <joint axis="0 -1 0" stiffness="0.002" range="-0.08726646259971647 0.7853981633974483" damping="0.002" solimplimit="0 .99 .01"/>
      <general gainprm="0.025"/>
    </default>
    <default class="mandible">
      <joint stiffness="0.002" range="-0.296705972839036 0.2617993877991494" springref="-0.314159265359" damping="0.002" solimplimit="0 .99 .01"/>
      <general gainprm="0.025"/>
    </default>
    <default class="caudal">
      <joint group="3" stiffness="1e-05" damping="0.002" solimplimit="0 .99 .01"/>
      <general gainprm="0.005"/>
      <default class="caudal_extend">
        <joint range="-0.08726646259971647 0.08726646259971647"/>
      </default>
      <default class="caudal_bend">
        <joint range="-0.08726646259971647 0.08726646259971647"/>
      </default>
    </default>
    <default class="hip">
      <joint armature="1e-05" damping="0.02" solimplimit="0 .99 .01"/>
      <general gainprm="0.2"/>
      <default class="hip_supinate">
        <joint range="-0.6981317007977318 0.5235987755982988"/>
      </default>
      <default class="hip_abduct">
        <joint range="-0.5235987755982988 1.047197551196598"/>
      </default>
      <default class="hip_extend">
        <joint range="-1.570796326794897 1.047197551196598"/>
        <general gainprm="0.3"/>
      </default>
    </default>
    <default class="knee">
      <joint range="-1.221730476396031 1.53588974175501" damping="0.005" solimplimit="0 .99 .01"/>
      <general gainprm="0.2"/>
    </default>
    <default class="ankle">
      <joint range="-0.1396263401595464 1.396263401595464" damping="0.003" solimplimit="0 .99 .01"/>
      <general gainprm="0.2"/>
    </default>
    <default class="toe">
      <joint range="0 0.8726646259971648" damping="0.001" solimplimit="0 .99 .01"/>
      <general gainprm="0.025"/>
    </default>
    <default class="scapula">
      <joint damping="0.005" solimplimit="0 .99 .01"/>
      <general gainprm="0.25"/>
      <default class="scapula_supinate">
        <joint pos="0 0.005000000000000001 0" range="-0.0174532925199433 0.1745329251994329"/>
      </default>
      <default class="scapula_abduct">
        <joint pos="0 0.005000000000000001 -0.01" range="-0.2617993877991494 0.2617993877991494"/>
      </default>
      <default class="scapula_extend">
        <joint pos="0 0 0" range="-0.03490658503988659 0.03490658503988659"/>
        <general gainprm="0.25"/>
      </default>
    </default>
    <default class="shoulder">
      <joint range="-1.308996938995747 0.8726646259971648" damping="0.005" solimplimit="0 .99 .01"/>
      <general gainprm="0.15"/>
    </default>
    <default class="shoulder_sup">
      <joint range="-0.05235987755982989 1.134464013796314" damping="0.005" solimplimit="0 .99 .01"/>
      <general gainprm="0.15"/>
    </default>
    <default class="elbow">
      <joint range="-1.308996938995747 0.6981317007977318" damping="0.003" solimplimit="0 .99 .01"/>
      <general gainprm="0.15"/>
    </default>
    <default class="wrist">
      <joint range="-0.3490658503988659 2.094395102393195" damping="0.002" solimplimit="0 .99 .01"/>
      <general gainprm="0.05"/>
    </default>
    <default class="finger">
      <joint range="0 1.570796326794897" damping="0.002" solimplimit="0 .99 .01"/>
      <general gainprm="0.025"/>
    </default>
    <default class="sensor">
      <site group="4"/>
    </default>
  </default>

  <worldbody>
    <geom name="floor" class="collision_floor" pos="0 0 -0.005" size="10 10 0.025" type="plane" material="grid"/>
    <light name="spotlight" mode="targetbody" target="torso"/>
    <body name="torso" pos="0.03099526054578288 2.058524937651458e-07 0.06808957263119967">
      <freejoint name="root"/>
      <light name="tracking_light" mode="targetbodycom" pos="0 0 3"/>
      <camera name="back" mode="targetbody" pos="-1 0 0.5" xyaxes="0 -1 0 1 0 2"/>
      <camera name="side" mode="targetbody" pos="0 -3 1" xyaxes="1 0 0 0 1 2"/>
      <camera name="side_alt" mode="targetbody" pos="0.5 -0.561 0.199" xyaxes="0.766 0.643 0.000 -0.162 0.192 0.968"/>
      <camera name="top" mode="targetbody" fovy="100.0" pos="0 0 1" zaxis="0 -0.2 0"/>
      <camera name="close_profile" mode="trackcom" pos=".3 -.3 0.25" xyaxes="1 1 0 -1 1 2"/>
      <camera name="close_side" mode="trackcom" pos="0 -.3 0.25" xyaxes="0 0 1 0 1 2"/>
      <geom name="collision_torso" class="no_collision" type="sphere" size="0.025" density="468.251260009" pos="-0.008200000000000001 0 0" euler="0 0.1745329251994329 0"/>
      <body name="scapula_L" pos="0.00656 0.00164 0.01148">
        <joint name="scapula_L_supinate" class="scapula_supinate" pos="0 -0.005000000000000001 0" axis="-0 -0 1"/>
        <joint name="scapula_L_abduct" class="scapula_abduct" pos="0 -0.005000000000000001 -0.01" axis="1 -0 -0"/>
        <joint name="scapula_L_extend" class="scapula_extend" pos="0 0 0" axis="0.3 1 0"/>
        <site name="shoulder_L" size="0.002" pos="0.0287 0.00984 -0.02542"/>
        <body name="upper_arm_L" pos="0.0287 0.00984 -0.02542">
          <joint name="shoulder_L" class="shoulder" axis="0 1 0"/>
          <joint name="shoulder_sup_L" class="shoulder_sup" axis="0 0 -1"/>
          <site name="elbow_L" type="cylinder" size="0.0006000000000000001 0.004" pos="-0.01593120836133218 0.01035528543486592 -0.02230369170586505" zaxis="0 1 0.2"/>
          <body name="lower_arm_L" pos="-0.01593120836133218 0.01035528543486592 -0.02230369170586505">
            <joint name="elbow_L" class="elbow" axis="0 1 0.2"/>
            <site name="wrist_L" type="cylinder" size="0.0008 0.0034" pos="0.02160265376479308 0.01260154802946263 -0.01980243261772699" zaxis="0 1 0"/>
            <body name="hand_L" pos="0.02160265376479308 0.01260154802946263 -0.01980243261772699">
              <joint name="wrist_L" class="wrist" axis="0.6 -1 0"/>
              <geom name="hand_L_collision" class="nonself_collision_primitive_paw" type="sphere" size="0.006470191588681792 0.003697252336389595 0.002218351401833757" density="2531.78122831" pos="0.001515873457919734 0.0007579367289598669 -0.004547620373759201" euler="-0.6981317007977318 0.8726646259971648 0.7853981633974483"/>
              <site name="finger_L" type="cylinder" size="0.0006000000000000001 0.005000000000000001" pos="0.003031746915839468 0.001515873457919734 -0.008337304018558537" zaxis="-0.2 1 0"/>
              <body name="finger_L" pos="0.003031746915839468 0.001515873457919734 -0.008337304018558537">
                <joint name="finger_L" class="finger" axis="-0.5 1 0"/>
                <geom name="finger_L0_collision" class="nonself_collision_primitive_paw" size="0.001848626168194797 0.003235095794340896" pos="0.004926588738239136 -0.0007579367289598669 0" euler="1.570796326794897 -1.308996938995747 0"/>
                <geom name="finger_L1_collision" class="nonself_collision_primitive_paw" size="0.001848626168194797 0.003697252336389595" pos="0.004547620373759201 0.001894841822399667 0" euler="1.570796326794897 -1.099557428756428 0"/>
                <geom name="finger_L2_collision" class="nonself_collision_primitive_paw" size="0.001848626168194797 0.003235095794340896" pos="0.002652778551359534 0.003789683644799335 0" euler="1.570796326794897 -0.9599310885968813 0"/>
                <site name="palm_L" class="sensor" type="box" size="0.004 0.004 0.002" pos="0.00492 0.00246 -0.00164" euler="0 0 0.4886921905584123"/>
              </body>
            </body>
            <geom name="radius_L_collision" class="no_collision" size="0.003732165792697991 0.01591658941003555" pos="0.01150545467526729 0.006850732667129763 -0.01222632491350886" quat="0.02376493230846292 0.7917721441518218 0.4232293467931716 0.4397829234413568"/>
            <geom name="ulna_L_collision" class="no_collision" size="0.004390783285527048 0.01317234985658114" pos="0.006749764363547758 0.004992418652633264 -0.009489848452311813" quat="0.01282244452041863 0.7446249872782607 0.4776065607195328 0.4661128472752391"/>
          </body>
          <geom name="humerus_L_collision" class="no_collision" size="0.007771321151869356 0.01554264230373871" pos="-0.007743344450064287 0.005787978890072665 -0.01198335273722202" quat="0.472560999180163 0.3450082805420177 0.0007016050154913519 0.8109592444517103"/>
        </body>
        <geom name="scapula_L_collision" class="no_collision" type="sphere" size="0.005005370825529099 0.01463182792067528 0.02431104406714439" density="513.564612303" pos="0.01757062251063465 0.008636916680112587 -0.01522952249267691" quat="0.1844194062696375 0.7692222855376651 0.4740322845517004 0.3867556738123709"/>
      </body>
      <body name="scapula_R" pos="0.00656 -0.00164 0.01148">
        <joint name="scapula_R_supinate" class="scapula_supinate" pos="0 0.005000000000000001 0" axis="0 0 -1"/>
        <joint name="scapula_R_abduct" class="scapula_abduct" pos="0 0.005000000000000001 -0.01" axis="-1 0 0"/>
        <joint name="scapula_R_extend" class="scapula_extend" pos="0 0 0" axis="-0.3 1 0"/>
        <site name="shoulder_R" size="0.002" pos="0.0287 -0.00984 -0.02542"/>
        <body name="upper_arm_R" pos="0.0287 -0.00984 -0.02542">
          <joint name="shoulder_R" class="shoulder" axis="0 1 0"/>
          <joint name="shoulder_sup_R" class="shoulder_sup" axis="-0 -0 1"/>
          <site name="elbow_R" type="cylinder" size="0.0006000000000000001 0.004" pos="-0.01593120836133218 -0.01035528543486592 -0.02230369170586505" zaxis="0 1 -0.2"/>
          <body name="lower_arm_R" pos="-0.01593120836133218 -0.01035528543486592 -0.02230369170586505">
            <joint name="elbow_R" class="elbow" axis="0 1 -0.2"/>
            <site name="wrist_R" type="cylinder" size="0.0008 0.0034" pos="0.02160265376479308 -0.01260154802946263 -0.01980243261772699" zaxis="0 1 0"/>
            <body name="hand_R" pos="0.02160265376479308 -0.01260154802946263 -0.01980243261772699">
              <joint name="wrist_R" class="wrist" axis="-0.6 -1 0"/>
              <geom name="hand_R_collision" class="nonself_collision_primitive_paw" type="sphere" size="0.006470191588681792 0.003697252336389595 0.002218351401833757" density="2531.78122831" pos="0.001515873457919734 -0.0007579367289598669 -0.004547620373759201" euler="0.6981317007977318 0.8726646259971648 -0.7853981633974483"/>
              <site name="finger_R" type="cylinder" size="0.0006000000000000001 0.005000000000000001" pos="0.003031746915839468 -0.001515873457919734 -0.008337304018558537" zaxis="0.2 1 0"/>
              <body name="finger_R" pos="0.003031746915839468 -0.001515873457919734 -0.008337304018558537">
                <joint name="finger_R" class="finger" axis="0.5 1 0"/>
                <geom name="finger_R0_collision" class="nonself_collision_primitive_paw" size="0.001848626168194797 0.003235095794340896" pos="0.004926588738239136 0.0007579367289598669 0" euler="1.570796326794897 1.308996938995747 0"/>
                <geom name="finger_R1_collision" class="nonself_collision_primitive_paw" size="0.001848626168194797 0.003697252336389595" pos="0.004547620373759201 -0.001894841822399667 0" euler="1.570796326794897 1.099557428756428 0"/>
                <geom name="finger_R2_collision" class="nonself_collision_primitive_paw" size="0.001848626168194797 0.003235095794340896" pos="0.002652778551359534 -0.003789683644799335 0" euler="1.570796326794897 0.9599310885968813 0"/>
                <site name="palm_R" class="sensor" type="box" size="0.004 0.004 0.002" pos="0.00492 -0.00246 -0.00164" euler="0 0 -0.4886921905584123"/>
              </body>
            </body>
            <geom name="radius_R_collision" class="no_collision" size="0.003732165792697991 0.01591658941003555" pos="0.01150546139578159 -0.0068511746740596 -0.01222632995360402" quat="0.4397828585901176 0.423230473256099 0.7917715587074765 0.02376557635859348"/>
            <geom name="ulna_R_collision" class="no_collision" size="0.004390783285527048 0.01317234985658114" pos="0.006749766930753688 -0.004992858736000205 -0.009489848507155575" quat="0.4661127828257156 0.4776067795325061 0.7446248854693838 0.01282254930824632"/>
          </body>
          <geom name="humerus_R_collision" class="no_collision" size="0.007771321151869356 0.01554264230373871" pos="-0.007743341889514446 -0.005788347560550173 -0.01198335067124012" quat="0.8109593935310486 0.0007013948082913995 0.3450082795040448 0.4725607444157158"/>
        </body>
        <geom name="scapula_R_collision" class="no_collision" type="sphere" size="0.005005370266735553 0.01463183127343655 0.02431103959679604" density="513.564646393" pos="0.01757062018850453 -0.008637295267367218 -0.01522952062810994" quat="0.3867556972129688 0.4740321312040688 0.7692223496423682 0.1844194839763772"/>
      </body>
    </body>
  </worldbody>
<!-- 
  <contact>
    <exclude name="pelvis:vertebra_C2" body1="pelvis" body2="vertebra_C2"/>
    <exclude name="pelvis:vertebra_C3" body1="pelvis" body2="vertebra_C3"/>
    <exclude name="pelvis:vertebra_C4" body1="pelvis" body2="vertebra_C4"/>
    <exclude name="vertebra_C1:vertebra_C3" body1="vertebra_C1" body2="vertebra_C3"/>
    <exclude name="vertebra_C1:vertebra_C4" body1="vertebra_C1" body2="vertebra_C4"/>
    <exclude name="vertebra_C2:vertebra_C4" body1="vertebra_C2" body2="vertebra_C4"/>
    <exclude name="vertebra_C3:vertebra_C5" body1="vertebra_C3" body2="vertebra_C5"/>
    <exclude name="vertebra_C4:vertebra_C6" body1="vertebra_C4" body2="vertebra_C6"/>
    <exclude name="vertebra_C5:vertebra_C7" body1="vertebra_C5" body2="vertebra_C7"/>
    <exclude name="vertebra_axis:skull" body1="vertebra_axis" body2="skull"/>
    <exclude name="pelvis:vertebra_C5" body1="pelvis" body2="vertebra_C5"/>
    <exclude name="pelvis:vertebra_C6" body1="pelvis" body2="vertebra_C6"/>
    <exclude name="vertebra_C2:vertebra_C5" body1="vertebra_C2" body2="vertebra_C5"/>
    <exclude name="vertebra_C3:vertebra_C6" body1="vertebra_C3" body2="vertebra_C6"/>
    <exclude name="vertebra_C4:vertebra_C7" body1="vertebra_C4" body2="vertebra_C7"/>
    <exclude name="upper_arm_L:upper_arm_R" body1="upper_arm_L" body2="upper_arm_R"/>
    <exclude name="upper_leg_L:vertebra_C1" body1="upper_leg_L" body2="vertebra_C1"/>
    <exclude name="upper_leg_L:vertebra_C2" body1="upper_leg_L" body2="vertebra_C2"/>
    <exclude name="upper_leg_R:vertebra_C1" body1="upper_leg_R" body2="vertebra_C1"/>
    <exclude name="upper_leg_R:vertebra_C2" body1="upper_leg_R" body2="vertebra_C2"/>
    <exclude name="vertebra_cervical_1:skull" body1="vertebra_cervical_1" body2="skull"/>
    <exclude name="vertebra_cervical_2:skull" body1="vertebra_cervical_2" body2="skull"/>
    <exclude name="upper_arm_L:torso" body1="upper_arm_L" body2="torso"/>
    <exclude name="upper_arm_R:torso" body1="upper_arm_R" body2="torso"/>
    <exclude name="lower_leg_L:pelvis" body1="lower_leg_L" body2="pelvis"/>
    <exclude name="lower_leg_R:pelvis" body1="lower_leg_R" body2="pelvis"/>

    <pair geom1="foot_L_collision" geom2="floor"/>
    <pair geom1="foot_R_collision" geom2="floor"/>
    <pair geom1="hand_L_collision" geom2="floor"/>
    <pair geom1="hand_R_collision" geom2="floor"/>
    <pair geom1="toe_L0_collision" geom2="floor"/>
    <pair geom1="toe_L1_collision" geom2="floor"/>
    <pair geom1="toe_L2_collision" geom2="floor"/>
    <pair geom1="toe_R0_collision" geom2="floor"/>
    <pair geom1="toe_R1_collision" geom2="floor"/>
    <pair geom1="toe_R2_collision" geom2="floor"/>
    <pair geom1="collision_torso" geom2="floor"/>

  </contact> -->

  <actuator>
    <general name="scapula_L_supinate" forcerange="-0.25 0.25" joint="scapula_L_supinate" dyntype="filter" biastype="affine" dynprm="0.04" gainprm="0.04799655442984406" biasprm="0.03926990816987241 -0.5"/>
    <general name="scapula_L_abduct" forcerange="-0.25 0.25" joint="scapula_L_abduct" dyntype="filter" biastype="affine" dynprm="0.04" gainprm="0.1308996938995747" biasprm="0 -0.5"/>
    <general name="scapula_L_extend" forcerange="-0.25 0.25" joint="scapula_L_extend" dyntype="filter" biastype="affine" dynprm="0.04" gainprm="0.0174532925199433" biasprm="0 -0.5"/>
    <general name="shoulder_L" forcerange="-0.15 0.15" joint="shoulder_L" dyntype="filter" biastype="affine" dynprm="0.04" gainprm="0.3272492347489368" biasprm="-0.06544984694978737 -0.3"/>
    <general name="shoulder_sup_L" forcerange="-0.15 0.15" joint="shoulder_sup_L" dyntype="filter" biastype="affine" dynprm="0.04" gainprm="0.1780235837034216" biasprm="0.1623156204354726 -0.3"/>
    <general name="elbow_L" forcerange="-0.15 0.15" joint="elbow_L" dyntype="filter" biastype="affine" dynprm="0.04" gainprm="0.3010692959690218" biasprm="-0.0916297857297023 -0.3"/>
    <general name="wrist_L" forcerange="-0.05 0.05" joint="wrist_L" dyntype="filter" biastype="affine" dynprm="0.04" gainprm="0.1221730476396031" biasprm="0.08726646259971647 -0.1"/>
    <general name="finger_L" forcerange="-0.025 0.025" joint="finger_L" dyntype="filter" biastype="affine" dynprm="0.04" gainprm="0.03926990816987241" biasprm="0.03926990816987241 -0.05"/>
    <general name="scapula_R_supinate" forcerange="-0.25 0.25" joint="scapula_R_supinate" dyntype="filter" biastype="affine" dynprm="0.04" gainprm="0.04799655442984406" biasprm="0.03926990816987241 -0.5"/>
    <general name="scapula_R_abduct" forcerange="-0.25 0.25" joint="scapula_R_abduct" dyntype="filter" biastype="affine" dynprm="0.04" gainprm="0.1308996938995747" biasprm="0 -0.5"/>
    <general name="scapula_R_extend" forcerange="-0.25 0.25" joint="scapula_R_extend" dyntype="filter" biastype="affine" dynprm="0.04" gainprm="0.0174532925199433" biasprm="0 -0.5"/>
    <general name="shoulder_R" forcerange="-0.15 0.15" joint="shoulder_R" dyntype="filter" biastype="affine" dynprm="0.04" gainprm="0.3272492347489368" biasprm="-0.06544984694978737 -0.3"/>
    <general name="shoulder_sup_R" forcerange="-0.15 0.15" joint="shoulder_sup_R" dyntype="filter" biastype="affine" dynprm="0.04" gainprm="0.1780235837034216" biasprm="0.1623156204354726 -0.3"/>
    <general name="elbow_R" forcerange="-0.15 0.15" joint="elbow_R" dyntype="filter" biastype="affine" dynprm="0.04" gainprm="0.3010692959690218" biasprm="-0.0916297857297023 -0.3"/>
    <general name="wrist_R" forcerange="-0.05 0.05" joint="wrist_R" dyntype="filter" biastype="affine" dynprm="0.04" gainprm="0.1221730476396031" biasprm="0.08726646259971647 -0.1"/>
    <general name="finger_R" forcerange="-0.025 0.025" joint="finger_R" dyntype="filter" biastype="affine" dynprm="0.04" gainprm="0.03926990816987241" biasprm="0.03926990816987241 -0.05"/>
  </actuator>
  <sensor>
    <subtreelinvel name="torso" body="torso"/>
  </sensor>
  <compiler meshdir="./"/>
</mujoco>